Workbook

Sheet Raw_Data
A1: Order_ID | B1: Order_Date | C1: Region | D1: Product | E1: Category | F1: Sales_Amount | G1: Profit | H1: Quantity
A2: ORD1064 | B2: 2024-07-13 | C2: West | D2: Stapler | E2: Office Supplies | F2: 6394.94 | G2: 2187.35 | H2: 9
A3: ORD1081 | B3: 2024-06-21 | C3: South | D3: Desk | E3: Furniture | F3: 88267.57 | G3: 20557.74 | H3: 5
A4: ORD1054 | B4: 2024-06-19 | C4: South | D4: Smartphone | E4: Electronics | F4: 150447.36 | G4: 19931.06 | H4: 3
A5: ORD1006 | B5: 2024-02-10 | C5: North | D5: Printer Paper | E5: Office Supplies | F5: 9584.44 | G5: 3759.3 | H5: 9
A6: ORD1044 | B6: 2024-02-05 | C6: North | D6: Notebook | E6: Office Supplies | F6: 2509.81 | G6: 987.17 | H6: 9
A7: ORD1056 | B7: 2024-06-05 | C7: North | D7: Desk | E7: Furniture | F7: 78838.27 | G7: 21761.75 | H7: 4
A8: ORD1011 | B8: 2024-01-29 | C8: East | D8: Whiteboard | E8: Office Supplies | F8: 14775.38 | G8: 5677.96 | H8: 4
A9: ORD1027 | B9: 2024-04-27 | C9: South | D9: Notebook | E9: Office Supplies | F9: 261.39 | G9: 94.91 | H9: 1
A10: ORD1087 | B10: 2024-01-11 | C10: North | D10: Pen Set | E10: Office Supplies | F10: 567.44 | G10: 181.54 | H10: 1
A11: ORD1023 | B11: 2024-03-25 | C11: North | D11: Notebook | E11: Office Supplies | F11: 943.13 | G11: 372.24 | H11: 3
A12: ORD1004 | B12: 2024-06-21 | C12: North | D12: Monitor | E12: Electronics | F12: 112003.37 | G12: 16972.02 | H12: 6
A13: ORD1077 | B13: 2024-04-19 | C13: North | D13: Smartphone | E13: Electronics | F13: 173683.91 | G13: 25232.89 | H13: 4
... A26: ORD1002 | B26: 2024-09-15 | C26: North | D26: Printer Paper | E26: Office Supplies | F26: 1030.73 | G26: 331.75 | H26: 1
A27: ORD1053 | B27: 2024-07-27 | C27: East | D27: Smartphone | E27: Electronics | H27: 2
A28: ORD1021 | B28: 2024-06-06 | C28: North | D28: Stapler | E28: Office Supplies | F28: 5477.4 | G28: 2152.12 | H28: 8
A29: ORD1042 | B29: 2024-08-22 | C29: East | D29: Tablet | E29: Electronics | F29: 186745.33 | G29: 36331.32 | H29: 7
A30: ORD1053 | B30: 2024-07-27 | C30: East | D30: Smartphone | E30: Electronics | F30: 86049.32 | G30: 16004.17 | H30: 2
A31: ORD1073 | B31: 2024-08-14 | C31: West | D31: Monitor | E31: Electronics | F31: 206346.19 | G31: 39111.94 | H31: 9
A32: ORD1065 | B32: 2024-06-04 | C32: South | D32: Whiteboard | E32: Office Supplies | F32: 17006.89 | G32: 6519.97 | H32: 5
A33: ORD1005 | B33: 2024-05-15 | C33: North | D33: Monitor | E33: Electronics | F33: 38307.75 | G33: 6297.62 | H33: 2
A34: ORD1008 | B34: 2024-08-20 | C34: South | D34: Chair | E34: Furniture | F34: 53277.36 | G34: 14279 | H34: 4
A35: ORD1079 | B35: 2024-07-13 | C35: West | D35: Sofa | E35: Furniture | F35: 27675.49 | G35: 8484.18 | H35: 1
A36: ORD1017 | B36: 2024-02-28 | C36: West | D36: Stapler | E36: Office Supplies | F36: 7979.28 | G36: 2402.95 | H36: 9
A37: ORD1096 | B37: 2024-10-30 | C37: East | D37: Whiteboard | E37: Office Supplies | F37: 27704.94 | G37: 10599.17 | H37: 8
A38: ORD1060 | B38: 2024-11-06 | C38: North | D38: Printer Paper | E38: Office Supplies | F38: 7693.66 | G38: 2549.43 | H38: 6
A39: ORD1022 | B39: 2024-09-05 | C39: South | D39: Smartphone | E39: Electronics | F39: 510338.18 | G39: 70715.19 | H39: 10
... A41: ORD1047 | B41: 2024-04-17 | C41: East | D41: Laptop | E41: Electronics | F41: 605228.2 | G41: 95732.35 | H41: 9
A42: ORD1052 | B42: 2024-01-21 | C42: South | D42: Desk | E42: Furniture | H42: 1
A43: ORD1050 | B43: 2024-02-27 | C43: East | D43: Monitor | E43: Electronics | F43: 191106.04 | G43: 35563.05 | H43: 9
A44: ORD1066 | B44: 2024-08-14 | C44: East | D44: Monitor | E44: Electronics | F44: 206399.69 | G44: 33483.17 | H44: 10
A45: ORD1001 | B45: 2024-12-12 | C45: North | D45: Tablet | E45: Electronics | F45: 110035.59 | G45: 22408.43 | H45: 4
A46: ORD1007 | B46: 2024-01-24 | C46: East | D46: Whiteboard | E46: Office Supplies | F46: 21487.32 | G46: 7960.13 | H46: 6
A47: ORD1094 | B47: 2024-11-21 | C47: East | D47: Monitor | E47: Electronics | F47: 141065.87 | G47: 31892 | H47: 8
A48: ORD1074 | B48: 2024-05-12 | C48: West | D48: Printer Paper | E48: Office Supplies | F48: 3863.15 | G48: 1342.32 | H48: 3
A49: ORD1003 | B49: 2024-05-22 | C49: North | D49: Notebook | E49: Office Supplies | F49: 2634.81 | G49: 908.8 | H49: 9
A50: ORD1086 | B50: 2024-04-24 | C50: North | D50: Chair | E50: Furniture | F50: 93487.57 | G50: 30401.41 | H50: 9
A51: ORD1067 | B51: 2024-03-27 | C51: West | D51: Notebook | E51: Office Supplies | F51: 2678.28 | G51: 1044.85 | H51: 9
A52: ORD1100 | B52: 2024-10-11 | C52: North | D52: Notebook | E52: Office Supplies | F52: 553.44 | G52: 188.53 | H52: 2
A53: ORD1018 | B53: 2024-01-02 | C53: East | D53: Stapler | E53: Office Supplies | F53: 1500.88 | G53: 474 | H53: 2
...

Sheet Cleaned_Data
A1: Order_ID | B1: Order_Date | C1: Region | D1: Product | E1: Category | F1: Sales_Amount | G1: Profit | H1: Quantity | I1: Total_Sales | J1: Profit_Margin_%
A2: ORD1064 | B2: 2024-07-13 | C2: West | D2: Stapler | E2: Office Supplies | F2: 6394.94 | G2: 2187.35 | H2: 9 | I2: =F2*H2 -> 57554.46 | J2: =IFERROR(G2/F2,0) -> 0.34204387
A3: ORD1081 | B3: 2024-06-21 | C3: South | D3: Desk | E3: Furniture | F3: 88267.57 | G3: 20557.74 | H3: 5 | I3: =F3*H3 -> 441337.85 | J3: =IFERROR(G3/F3,0) -> 0.23290253
A4: ORD1054 | B4: 2024-06-19 | C4: South | D4: Smartphone | E4: Electronics | F4: 150447.36 | G4: 19931.06 | H4: 3 | I4: =F4*H4 -> 451342.08 | J4: =IFERROR(G4/F4,0) -> 0.13247863
A5: ORD1006 | B5: 2024-02-10 | C5: North | D5: Printer Paper | E5: Office Supplies | F5: 9584.44 | G5: 3759.3 | H5: 9 | I5: =F5*H5 -> 86259.96 | J5: =IFERROR(G5/F5,0) -> 0.39222949
A6: ORD1044 | B6: 2024-02-05 | C6: North | D6: Notebook | E6: Office Supplies | F6: 2509.81 | G6: 987.17 | H6: 9 | I6: =F6*H6 -> 22588.29 | J6: =IFERROR(G6/F6,0) -> 0.39332459
A7: ORD1056 | B7: 2024-06-05 | C7: North | D7: Desk | E7: Furniture | F7: 78838.27 | G7: 21761.75 | H7: 4 | I7: =F7*H7 -> 315353.08 | J7: =IFERROR(G7/F7,0) -> 0.27603028
A8: ORD1011 | B8: 2024-01-29 | C8: East | D8: Whiteboard | E8: Office Supplies | F8: 14775.38 | G8: 5677.96 | H8: 4 | I8: =F8*H8 -> 59101.52 | J8: =IFERROR(G8/F8,0) -> 0.38428521
A9: ORD1027 | B9: 2024-04-27 | C9: South | D9: Notebook | E9: Office Supplies | F9: 261.39 | G9: 94.91 | H9: 1 | I9: =F9*H9 -> 261.39 | J9: =IFERROR(G9/F9,0) -> 0.36309729
A10: ORD1087 | B10: 2024-01-11 | C10: North | D10: Pen Set | E10: Office Supplies | F10: 567.44 | G10: 181.54 | H10: 1 | I10: =F10*H10 -> 567.44 | J10: =IFERROR(G10/F10,0) -> 0.3199281
A11: ORD1023 | B11: 2024-03-25 | C11: North | D11: Notebook | E11: Office Supplies | F11: 943.13 | G11: 372.24 | H11: 3 | I11: =F11*H11 -> 2829.39 | J11: =IFERROR(G11/F11,0) -> 0.39468578
A12: ORD1004 | B12: 2024-06-21 | C12: North | D12: Monitor | E12: Electronics | F12: 112003.37 | G12: 16972.02 | H12: 6 | I12: =F12*H12 -> 672020.22 | J12: =IFERROR(G12/F12,0) -> 0.15153133
A13: ORD1077 | B13: 2024-04-19 | C13: North | D13: Smartphone | E13: Electronics | F13: 173683.91 | G13: 25232.89 | H13: 4 | I13: =F13*H13 -> 694735.64 | J13: =IFERROR(G13/F13,0) -> 0.14528053
... A101: ORD1098 | B101: 2024-04-18 | C101: West | D101: Chair | E101: Furniture | F101: 106107.44 | G101: 26334.17 | H101: 8 | I101: =F101*H101 -> 848859.52 | J101: =IFERROR(G101/F101,0) -> 0.24818401

Sheet Pivot_Region
A1: Sales by Region
A3: Region | B3: Total Sales | C3: Total Profit | D3: Avg Profit Margin %
A4: North | B4: =SUMIF(Cleaned_Data!C$2:C$101,A4,Cleaned_Data!I$2:I$101) -> 17289756 | C4: =SUMIF(Cleaned_Data!C$2:C$101,A4,Cleaned_Data!G$2:G$101) -> 590298.82 | D4: =IFERROR(C4/B4,0) -> 0.034141536
A5: South | B5: =SUMIF(Cleaned_Data!C$2:C$101,A5,Cleaned_Data!I$2:I$101) -> 19632752 | C5: =SUMIF(Cleaned_Data!C$2:C$101,A5,Cleaned_Data!G$2:G$101) -> 514719.04 | D5: =IFERROR(C5/B5,0) -> 0.026217366
A6: East | B6: =SUMIF(Cleaned_Data!C$2:C$101,A6,Cleaned_Data!I$2:I$101) -> 29443189 | C6: =SUMIF(Cleaned_Data!C$2:C$101,A6,Cleaned_Data!G$2:G$101) -> 773889.15 | D6: =IFERROR(C6/B6,0) -> 0.026284148
A7: West | B7: =SUMIF(Cleaned_Data!C$2:C$101,A7,Cleaned_Data!I$2:I$101) -> 13851711 | C7: =SUMIF(Cleaned_Data!C$2:C$101,A7,Cleaned_Data!G$2:G$101) -> 417589.61 | D7: =IFERROR(C7/B7,0) -> 0.030147151
A8: TOTAL | B8: =SUM(B4:B7) -> 80217408 | C8: =SUM(C4:C7) -> 2296496.6

Sheet Pivot_Product
A1: Sales by Product
A3: Product | B3: Category | C3: Total Sales | D3: Total Profit
A4: Laptop | B4: Electronics | C4: =SUMIF(Cleaned_Data!D$2:D$101,A4,Cleaned_Data!I$2:I$101) -> 17142831 | D4: =SUMIF(Cleaned_Data!D$2:D$101,A4,Cleaned_Data!G$2:G$101) -> 424800
A5: Smartphone | B5: Electronics | C5: =SUMIF(Cleaned_Data!D$2:D$101,A5,Cleaned_Data!I$2:I$101) -> 23622759 | D5: =SUMIF(Cleaned_Data!D$2:D$101,A5,Cleaned_Data!G$2:G$101) -> 533377.87
A6: Tablet | B6: Electronics | C6: =SUMIF(Cleaned_Data!D$2:D$101,A6,Cleaned_Data!I$2:I$101) -> 7999712.4 | D6: =SUMIF(Cleaned_Data!D$2:D$101,A6,Cleaned_Data!G$2:G$101) -> 257592.82
A7: Monitor | B7: Electronics | C7: =SUMIF(Cleaned_Data!D$2:D$101,A7,Cleaned_Data!I$2:I$101) -> 8611326.5 | D7: =SUMIF(Cleaned_Data!D$2:D$101,A7,Cleaned_Data!G$2:G$101) -> 193658.73
A8: Headphones | B8: Electronics | C8: =SUMIF(Cleaned_Data!D$2:D$101,A8,Cleaned_Data!I$2:I$101) -> 35372.88 | D8: =SUMIF(Cleaned_Data!D$2:D$101,A8,Cleaned_Data!G$2:G$101) -> 2420.43
A9: Chair | B9: Furniture | C9: =SUMIF(Cleaned_Data!D$2:D$101,A9,Cleaned_Data!I$2:I$101) -> 4587820.6 | D9: =SUMIF(Cleaned_Data!D$2:D$101,A9,Cleaned_Data!G$2:G$101) -> 154069.11
A10: Desk | B10: Furniture | C10: =SUMIF(Cleaned_Data!D$2:D$101,A10,Cleaned_Data!I$2:I$101) -> 1094037.5 | D10: =SUMIF(Cleaned_Data!D$2:D$101,A10,Cleaned_Data!G$2:G$101) -> 85910.74
A11: Bookshelf | B11: Furniture | C11: =SUMIF(Cleaned_Data!D$2:D$101,A11,Cleaned_Data!I$2:I$101) -> 330169.5 | D11: =SUMIF(Cleaned_Data!D$2:D$101,A11,Cleaned_Data!G$2:G$101) -> 22580.56
A12: Cabinet | B12: Furniture | C12: =SUMIF(Cleaned_Data!D$2:D$101,A12,Cleaned_Data!I$2:I$101) -> 3258388.9 | D12: =SUMIF(Cleaned_Data!D$2:D$101,A12,Cleaned_Data!G$2:G$101) -> 131437.41
A13: Sofa | B13: Furniture | C13: =SUMIF(Cleaned_Data!D$2:D$101,A13,Cleaned_Data!I$2:I$101) -> 11923605 | D13: =SUMIF(Cleaned_Data!D$2:D$101,A13,Cleaned_Data!G$2:G$101) -> 402395.72
A14: Pen Set | B14: Office Supplies | C14: =SUMIF(Cleaned_Data!D$2:D$101,A14,Cleaned_Data!I$2:I$101) -> 14830.5 | D14: =SUMIF(Cleaned_Data!D$2:D$101,A14,Cleaned_Data!G$2:G$101) -> 1423.9
A15: Notebook | B15: Office Supplies | C15: =SUMIF(Cleaned_Data!D$2:D$101,A15,Cleaned_Data!I$2:I$101) -> 221107.21 | D15: =SUMIF(Cleaned_Data!D$2:D$101,A15,Cleaned_Data!G$2:G$101) -> 9703.7
... A18: Whiteboard | B18: Office Supplies | C18: =SUMIF(Cleaned_Data!D$2:D$101,A18,Cleaned_Data!I$2:I$101) -> 792916.95 | D18: =SUMIF(Cleaned_Data!D$2:D$101,A18,Cleaned_Data!G$2:G$101) -> 49426.38

Sheet Pivot_Monthly
A1: Monthly Sales Trend (2024)
A3: Month | B3: Month_Num | C3: Total Sales | D3: Total Profit
A4: Jan | B4: 1 | C4: =SUMPRODUCT((MONTH(Cleaned_Data!B$2:B$101)=B4)*Cleaned_Data!I$2:I$101) -> 5751618.1 | D4: =SUMPRODUCT((MONTH(Cleaned_Data!B$2:B$101)=B4)*Cleaned_Data!G$2:G$101) -> 217115.18
A5: Feb | B5: 2 | C5: =SUMPRODUCT((MONTH(Cleaned_Data!B$2:B$101)=B5)*Cleaned_Data!I$2:I$101) -> 13395425 | D5: =SUMPRODUCT((MONTH(Cleaned_Data!B$2:B$101)=B5)*Cleaned_Data!G$2:G$101) -> 360952.38
A6: Mar | B6: 3 | C6: =SUMPRODUCT((MONTH(Cleaned_Data!B$2:B$101)=B6)*Cleaned_Data!I$2:I$101) -> 4850996.4 | D6: =SUMPRODUCT((MONTH(Cleaned_Data!B$2:B$101)=B6)*Cleaned_Data!G$2:G$101) -> 114042.27
A7: Apr | B7: 4 | C7: =SUMPRODUCT((MONTH(Cleaned_Data!B$2:B$101)=B7)*Cleaned_Data!I$2:I$101) -> 16299092 | D7: =SUMPRODUCT((MONTH(Cleaned_Data!B$2:B$101)=B7)*Cleaned_Data!G$2:G$101) -> 428590.72
A8: May | B8: 5 | C8: =SUMPRODUCT((MONTH(Cleaned_Data!B$2:B$101)=B8)*Cleaned_Data!I$2:I$101) -> 4432731.7 | D8: =SUMPRODUCT((MONTH(Cleaned_Data!B$2:B$101)=B8)*Cleaned_Data!G$2:G$101) -> 130670.45
A9: Jun | B9: 6 | C9: =SUMPRODUCT((MONTH(Cleaned_Data!B$2:B$101)=B9)*Cleaned_Data!I$2:I$101) -> 3419212.5 | D9: =SUMPRODUCT((MONTH(Cleaned_Data!B$2:B$101)=B9)*Cleaned_Data!G$2:G$101) -> 155498.95
A10: Jul | B10: 7 | C10: =SUMPRODUCT((MONTH(Cleaned_Data!B$2:B$101)=B10)*Cleaned_Data!I$2:I$101) -> 604340.54 | D10: =SUMPRODUCT((MONTH(Cleaned_Data!B$2:B$101)=B10)*Cleaned_Data!G$2:G$101) -> 54084.94
A11: Aug | B11: 8 | C11: =SUMPRODUCT((MONTH(Cleaned_Data!B$2:B$101)=B11)*Cleaned_Data!I$2:I$101) -> 13676281 | D11: =SUMPRODUCT((MONTH(Cleaned_Data!B$2:B$101)=B11)*Cleaned_Data!G$2:G$101) -> 365610.49
A12: Sep | B12: 9 | C12: =SUMPRODUCT((MONTH(Cleaned_Data!B$2:B$101)=B12)*Cleaned_Data!I$2:I$101) -> 6882916.3 | D12: =SUMPRODUCT((MONTH(Cleaned_Data!B$2:B$101)=B12)*Cleaned_Data!G$2:G$101) -> 141628.08
A13: Oct | B13: 10 | C13: =SUMPRODUCT((MONTH(Cleaned_Data!B$2:B$101)=B13)*Cleaned_Data!I$2:I$101) -> 2336323.5 | D13: =SUMPRODUCT((MONTH(Cleaned_Data!B$2:B$101)=B13)*Cleaned_Data!G$2:G$101) -> 66063.96
A14: Nov | B14: 11 | C14: =SUMPRODUCT((MONTH(Cleaned_Data!B$2:B$101)=B14)*Cleaned_Data!I$2:I$101) -> 5917811.6 | D14: =SUMPRODUCT((MONTH(Cleaned_Data!B$2:B$101)=B14)*Cleaned_Data!G$2:G$101) -> 176233.01
A15: Dec | B15: 12 | C15: =SUMPRODUCT((MONTH(Cleaned_Data!B$2:B$101)=B15)*Cleaned_Data!I$2:I$101) -> 2650658.3 | D15: =SUMPRODUCT((MONTH(Cleaned_Data!B$2:B$101)=B15)*Cleaned_Data!G$2:G$101) -> 86006.19

Sheet KPI_Summary
A1: 📊 KPI Summary Dashboard
A2: Total Revenue | B2: =SUM(Cleaned_Data!I2:I101) -> 80217408
A3: Total Profit | B3: =SUM(Cleaned_Data!G2:G101) -> 2296496.6
A4: Overall Profit Margin % | B4: =IFERROR(B3/B2,0) -> 0.028628407
A5: Total Orders | B5: =COUNTA(Cleaned_Data!A2:A101) -> 100
A6: Avg Order Value | B6: =IFERROR(B2/B5,0) -> 802174.08
A7: Best Region | B7: =INDEX(Pivot_Region!A4:A7,MATCH(MAX(Pivot_Region!B4:B7),Pivot_Region!B4:B7,0)) -> East
A8: Top Product | B8: =INDEX(Pivot_Product!A4:A18,MATCH(MAX(Pivot_Product!C4:C18),Pivot_Product!C4:C18,0)) -> Smartphone
